# 8.30-Promise 训练题

## 描述

Promise 基础题(由浅入深)

## Promise

**题目一**

```js
const promise = new Promise((resolve, reject) => {
  console.log(1)
  resolve('success')
  console.log(2)
})
promise.then(() => {
  console.log(3)
})
console.log(4)
```
<details>
  <summary>答案</summary>
  <div>1</div>
  <div>2</div>
  <div>4</div>
  <div>3</div>
</details>

**题目二**

```js
const promise = new Promise((resolve, reject) => {
  console.log(1)
  console.log(2)
})
promise.then(() => {
  console.log(3)
})
console.log(4)
```
<details>
  <summary>答案</summary>
  <div>1</div>
  <div>2</div>
  <div>4</div>
</details>

**题目三**

```js
 const promise1 = new Promise((resolve, reject) => {
   console.log('promise1')
   resolve('resolve1')
 })
 const promise2 = promise1.then(res => {
   console.log(res)
 })
 console.log('1', promise1);
 console.log('2', promise2);

 // 答案
 'promise1'
 '1' Promise{<resolved>: 'resolve1'}
 '2' Promise{<pending>}
 'resolve1'
```

**题目四**

```js
const fn = () => (new Promise((resolve, reject) => {
   console.log(1);
   resolve('success')
 }))
 fn().then(res => {
   console.log(res)
 })
 console.log('start')
```
<details>
  <summary>答案</summary>
  <div>1</div>
  <div>start</div>
  <div>success</div>
</details>

## Promise +setTimeout

**题目一**

```js
console.log('start')
setTimeout(() => {
  console.log('time')
})
Promise.resolve().then(() => {
  console.log('resolve')
})
console.log('end')
```
<details>
  <summary>答案</summary>
  <div>start</div>
  <div>end</div>
  <div>resolve</div>
  <div>time</div>
</details>

**题目二**

```js
const promise = new Promise((resolve, reject) => {
  console.log(1)
  setTimeout(() => {
    console.log('timerStart')
    resolve('success')
    console.log('timerEnd')
  }, 0)
  console.log(2)
})
promise.then(res => {
  console.log(res)
})
console.log(4)
```

<details>
  <summary>答案</summary>
  <div>1</div>
  <div>2</div>
  <div>4</div>
  <div>timerStart</div>
  <div>timerEnd</div>
  <div>success</div>
</details>

**题目三**

```js
setTimeout(() => {
  console.log('timer1')
  Promise.resolve().then(() => {
    console.log('promise')
  })
}, 0)
setTimeout(() => {
  console.log('timer2')
}, 0)
console.log('start')
```

<details>
  <summary>答案</summary>
  <div>start</div>
  <div>timer1</div>
  <div>promise</div>
  <div>timer2</div>
</details>

**题目四**

```js
 const promise1 = new Promise((resolve, reject) => {
   setTimeout(() => {
     resolve('success')
   }, 1000)
 })
 const promise2 = promise1.then(() => {
   throw new Error('error!!!')
 })
 console.log('promise1', promise1)
 console.log('promise2', promise2)
 setTimeout(() => {
   console.log('promise1', promise1)
   console.log('promise2', promise2)
 }, 2000)
 // 答案
 'promise1': promise{<pedding>}
 'promise2': promise{<pedding>}
 'promise1': promise{<resolve>:'success'}
 'promise2': promise{<rejected>:Error: error!!!}
```



## Promise 中的 then、catch、finally

`知识补充`

- Promise 的状态一经改变就不能再改变。(见题 1)

- .then 和.catch 都会返回一个新的 Promise。
- catch 不管被连接到哪里，都能捕获上层未捕捉过的错误。(见题 2)
- 在 Promise 中，返回任意一个非 promise 的值都会被包裹成 promise 对象，例如 return 2 会被包装为 return Promise.resolve(2)。
- Promise 的 .then 或者 .catch 可以被调用多次, 但如果 Promise 内部的状态一经改变，并且有了一个值，那么后续每次调用.then 或者.catch 的时候都会直接拿到该值。(见题 5)
- .then 或者 .catch 中 return 一个 error 对象并不会抛出错误，所以不会被后续的 .catch 捕获。(见题 6)
- .then 或 .catch 返回的值不能是 promise 本身，否则会造成死循环。(见题 6)
- .then 或者 .catch 的参数期望是函数，传入非函数则会发生**值透传**。(见题 7)
- .then 方法是能接收两个参数的，第一个是处理成功的函数，第二个是处理失败的函数，再某些时候你可以认为 catch 是.then 第二个参数的简便写法。
- .finally 方法也是返回一个 Promise，他在 Promise 结束的时候，无论结果为 resolved 还是 rejected，都会执行里面的回调函数

**题目一**

```js
const promise = new Promise((resolve, reject) => {
  resolve('success1')
  reject('error')
  resolve('success2')
})
promise
  .then(res => {
    console.log('then: ', res)
  })
  .catch(err => {
    console.log('catch: ', err)
  })
```
<details>
  <summary>答案</summary>
  <div>"then: success1"</div>
</details>

**题目二**

```js
const promise = new Promise((resolve, reject) => {
   reject("error");
   resolve("success2");
 });
 promise
 .then(res => {
     console.log("then1: ", res);
   }).then(res => {
     console.log("then2: ", res);
   }).catch(err => {
     console.log("catch: ", err);
   }).then(res => {
     console.log("then3: ", res);
   })
```
<details>
  <summary>答案</summary>
  <div>"catch: " "error"</div>
  <div>"then3: " undefined</div>
  <br />
  <div style="color:#c7254e">
  验证了第三个结论，catch不管被连接到哪里，都能捕获上层未捕捉过的错误<br />
  至于then3也会被执行，那是因为catch()也会返回一个Promise，且由于这个Promise没有返回值，所以打印出来的是undefined
  </div>
</details>

**题目三**

```js
Promise.resolve(1)
   .then(res => {
     console.log(res);
     return 2;
   })
   .catch(err => {
     return 3;
   })
   .then(res => {
     console.log(res);
   });
```
<details>
  <summary>答案</summary>
  <div>1</div>
  <div>2</div>
  <br />
  <div style="color:#c7254e">
  Promise可以链式调用，不过promise 每次调用 .then 或者 .catch 都会返回一个新的 promise，从而实现了链式调用, 它并不像一般我们任务的链式调用一样return Promise
  <br />
  上面的输出结果之所以依次打印出1和2，那是因为resolve(1)之后走的是第一个then方法，并没有走catch里，所以第二个then中的res得到的实际上是第一个then的返回值。
  且return 2会被包装成resolve(2)
  </div>
</details>

**题目四**

```js
Promise.reject(1)
   .then(res => {
     console.log(res);
     return 2;
   })
   .catch(err => {
     console.log(err);
     return 3
   })
   .then(res => {
     console.log(res);
   });
 
```
<details>
  <summary>答案</summary>
  <div>1</div>
  <div>3</div>
  <br />
  <div style="color:#c7254e">因为reject(1)此时走的就是catch，且第二个then中的res得到的就是catch中的返回值</div>
</details>

**题目五**

```js
const promise = new Promise((resolve, reject) => {
   setTimeout(() => {
     console.log('timer')
     resolve('success')
   }, 1000)
 })
 const start = Date.now();
 promise.then(res => {
   console.log(res, Date.now() - start)
 })
 promise.then(res => {
   console.log(res, Date.now() - start)
 })
 /*
 当然，如果你足够快的话，也可能两个都是1001。
 Promise 的 .then 或者 .catch 可以被调用多次，但这里 Promise 构造函数只执行一次。或者说 promise 内部状态一经改变，并且有了一个值，那么后续每次调用 .then 或者 .catch 都会直接拿到该值。
 */
```
<details>
  <summary>答案</summary>
  <div>timer</div>
  <div> 'success' 1001</div>
  <div> 'success' 1002</div>
</details>

**题目六**

```js
 Promise.resolve().then(() => {
   return new Error('error!!!')
 }).then(res => {
   console.log("then: ", res)
 }).catch(err => {
   console.log("catch: ", err)
 })
 
 /*
 这也验证了第4点和第6点，返回任意一个非 promise 的值都会被包裹成 promise 对象，因此这里的return new Error('error!!!')也被包裹成了return Promise.resolve(new Error('error!!!'))。
 
 当然如果你抛出一个错误的话，可以用下面👇两的任意一种：
 */
 return Promise.reject(new Error('error!!!'));
 // or
 throw new Error('error!!!')
```

<details>
  <summary>答案</summary>
  <div>'then' : "Error: error!!!"</div>
</details>

**题目七**

```js
Promise.resolve(1).then(2).then(Promise.resolve(3)).then(console.log) //答案
1 /*
 其实你只要记住原则8：.then 或者 .catch 的参数期望是函数，传入非函数则会发生值透传。
 第一个then和第二个then中传入的都不是函数，一个是数字类型，一个是对象类型，因此发生了透传，将resolve(1) 的值直接传到最后一个then里。
 */
```
<details>
  <summary>答案</summary>
  <div>1</div>
  <br />
  <div style="color:#c7254e">
  记住原则：.then 或者 .catch 的参数期望是函数，传入非函数则会发生值透传<br />
  第一个then和第二个then中传入的都不是函数，一个是数字类型，一个是对象类型，因此发生了透传，将resolve(1) 的值直接传到最后一个then里
  </div>
</details>

## async/await 的几道题

**题目一**

```js
async function async1() {
  console.log('async1 start')
  await async2()
  console.log('async1 end')
}
async function async2() {
  console.log('async2')
}
async1()
console.log('start') //答案
```

将上述 async awiat 转为 promise.then

```js
async function async1() {
  console.log('async1 start') // 原来代码 // await async2(); // console.log("async1 end"); // 转换后代码
  new Promise(resolve => {
    console.log('async2')
    resolve()
  }).then(res => console.log('async1 end'))
}
async function async2() {
  console.log('async2')
}
async1()
console.log('start')
```
<details>
  <summary>答案</summary>
  <div>async1 start</div>
  <div>async2</div>
  <div>start</div>
  <div>async1 end</div>
</details>

**题目二**

```js
async function async1() {
   console.log("async1 start");
   await async2();
   console.log("async1 end");
 }
 async function async2() {
   setTimeout(() => {
     console.log('timer')
   }, 0)
   console.log("async2");
 }
 async1();
 console.log("start")
```
<details>
  <summary>答案</summary>
  <div>async1 start</div>
  <div>async2</div>
  <div>start</div>
  <div>async1 end</div>
  <div>timer</div>
  <br />
  <div style="color:#c7254e">tip: 定时器始终还是最后执行的，它被放到下一条宏任务的延迟队列中。</div>
</details>

**题目三**

```js
async function async1() {
   console.log("async1 start");
   await async2();
   console.log("async1 end");
   setTimeout(() => {
     console.log('timer1') // 3
   }, 0)
 }
 async function async2() {
   setTimeout(() => {
     console.log('timer2')  // 1
   }, 0)
   console.log("async2");
 }
 async1();
 setTimeout(() => {
   console.log('timer3')  // 2
 }, 0)
 console.log("start")
```
<details>
  <summary>答案</summary>
  <div>async1 start</div>
  <div>start</div>
  <div>async1 end</div>
  <div>timer2</div>
  <div>timer3</div>
  <div>timer1</div>
  <br />
  <div style="color:#c7254e">tip: 定时器谁先执行，你只需要关注谁先被调用的以及延迟时间是多少，这道题中延迟时间都是0，所以只要关注谁先被调用的。</div>
</details>

## async 处理错误

**题目一**

```js
async function async1 () {
   await async2();
   console.log('async1');
   return 'async1 success'
 }
 async function async2 () {
   return new Promise((resolve, reject) => {
     console.log('async2')
     reject('error')
   })
 }
 async1().then(res => console.log(res))
```

<details>
  <summary>答案</summary>
  <div>async2</div>
  <div>Uncaught (in promise) error</div>
  <br />
  <div style="color:#c7254e">tip: 如果在async函数中抛出了错误，则终止错误结果，不会继续向下执行。</div>
</details>

**题目二**

```js
//如果想要使得错误的地方不影响async函数后续的执行的话，可以使用try catch
async function async1() {
  try {
    await Promise.reject('error!!!')
  } catch (e) {
    console.log(e)
  }
  console.log('async1')
  return Promise.resolve('async1 success')
}
async1().then(res => console.log(res))
console.log('script start')
```

<details>
  <summary>答案</summary>
  <div>script start</div>
  <div>error!!!</div>
  <div>async1</div>
  <div>async1 success</div>
</details>
